Workbook

Sheet rawdata
A1: mode | B1: paperId | C1: title | D1: publication_date | E1: year | F1: publication_types | G1: fields_of_study | H1: influential_citation_count | I1: citation_count | J1: abstract | K1: external_ids | L1: doi | M1: is_open_access | N1: open_access_pdf_url | O1: journal_pages_range | P1: pages_total | Q1: references_pages | R1: references_count | S1: _max_cited_year | T1: authors_hindex_list | U1: mean_author_hindex
A2: PRECISE | B2: d7d9107de19eba8228bc599f53f013245760caee | C2: A Survey of Data Mining and Machine Learning Methods for Cyber Security Intrusion Detection | D2: 2017-04-13 | E2: 2017 | F2: Review | G2: Engineering | H2: 106 | I2: 1461 | K2: {"CorpusId": 44606951, "MAG": "2605388774"} | M2: FALSE | O2: 406-412 | P2: 7 | R2: 14 | T2: 1; 2; 1; 2 | U2: 1.5
A3: PRECISE | B3: dab11c890b9924c8bfcb09bf8a9b1fbd1e2bbffc | C3: Processing flows of information: From data stream to complex event processing | D3: 2012-06-01 | E3: 2012 | F3: JournalArticle; Review | G3: Computer Science | H3: 84 | I3: 995 | K3: {"CorpusId": 8728283, "DBLP": "journals/csur/CugolaM12", "DOI": "10.1145/2187671.2187677", "MAG": "1973026225"} | L3: 10.1145/2187671.2187677 | M3: FALSE | O3: 15:1-15:62 | R3: 181 | T3: 35; 24 | U3: 29.5
A4: PRECISE | B4: 1dc23940f830a1aede366ac9654b5d499c14bcef | C4: A Survey of Defense Mechanisms Against Distributed Denial of Service (DDoS) Flooding Attacks | D4: 2013-03-28 | E4: 2013 | F4: JournalArticle; Review | G4: Computer Science | H4: 77 | I4: 1307 | K4: {"CorpusId": 206584087, "DBLP": "journals/comsur/ZargarJT13", "DOI": "10.1109/SURV.2013.031413.00127", "MAG": "2162969618"} | L4: 10.1109/surv.2013.031413.00127 | M4: TRUE | N4: http://d-scholarship.pitt.edu/19225/1/FinalVersion.pdf | O4: 2046-2069 | P4: 24 | R4: 147 | T4: 9; 39; 33 | U4: 27
A5: PRECISE | B5: 4db2f23a5ad2259b90aa9b0545d27cd44337515a | C5: Intrusion detection system: A comprehensive review | F5: JournalArticle; Review | G5: Computer Science | H5: 71 | I5: 1426 | K5: {"CorpusId": 18434328, "DBLP": "journals/jnca/LiaoLLT13", "DOI": "10.1016/j.jnca.2012.09.004", "MAG": "433644524"} | L5: 10.1016/j.jnca.2012.09.004 | M5: FALSE | O5: 16-24 | P5: 9 | R5: 71 | T5: 2; 15; 4; 4 | U5: 6.25
A6: PRECISE | B6: e467ff1ea3a0c535a0cef87f7e0daa414d524d9d | C6: Network Anomaly Detection: Methods, Systems and Tools | D6: 2014-01-21 | E6: 2014 | F6: JournalArticle; Review | G6: Computer Science | H6: 71 | I6: 1184 | K6: {"CorpusId": 4937576, "DBLP": "journals/comsur/BhuyanBK14", "DOI": "10.1109/SURV.2013.052213.00046", "MAG": "1966809779"} | L6: 10.1109/surv.2013.052213.00046 | M6: FALSE | O6: 303-336 | P6: 34 | R6: 227 | T6: 21; 39; 44 | U6: 34.66666666666666
A7: PRECISE | B7: 38e81867da601ae6877dd9ce2c1e1aa085852ecb | C7: Survey of intrusion detection systems: techniques, datasets and challenges | D7: 2019-07-01 | E7: 2019 | F7: JournalArticle; Review | G7: Computer Science | H7: 63 | I7: 1287 | J7: Cyber-attacks are becoming more sophisticated and thereby presenting increasing challenges in accurately detecting intrusions. Failure to prevent the intrusions could degrade the credibility of security services, e.g. data confidentiality, integrity, and availability. Numerous intrusion detection methods have been proposed in the literature to tackle computer security threats, which can be broadly classified into Signature-based Intrusion Detection Systems (SIDS) and Anomaly-based Intrusion Detection Systems (AIDS). This survey paper presents a taxonomy of contemporary IDS, a comprehensive review of notable recent works, and an overview of the datasets commonly used for evaluation purposes. It also presents evasion techniques used by attackers to avoid detection and discusses future research challenges to counter such techniques so as to make computer systems more secure. | K7: {"CorpusId": 197645932, "DBLP": "journals/cybersec/KhraisatGVK19", "DOI": "10.1186/s42400-019-0038-7", "MAG": "2958285686"} | L7: 10.1186/s42400-019-0038-7 | M7: TRUE | N7: https://cybersecurity.springeropen.com/track/pdf/10.1186/s42400-019-0038-7 | R7: 124 | S7: 2018 | T7: 14; 27; 27; 36 | U7: 26
A8: PRECISE | B8: 1c65649ffb61144f867aa1dc526ddaac19b3cecd | C8: A survey of intrusion detection in Internet of Things | D8: 2017-04-15 | E8: 2017 | F8: JournalArticle; Review | G8: Computer Science | H8: 47 | I8: 891 | K8: {"CorpusId": 31714, "DBLP": "journals/jnca/ZarpelaoMKA17", "DOI": "10.1016/j.jnca.2017.02.009", "MAG": "2590373591"} | L8: 10.1016/j.jnca.2017.02.009 | M8: FALSE | O8: 25-37 | P8: 13 | R8: 90 | T8: 16; 11; 3; 3 | U8: 8.25
A9: PRECISE | B9: 2eea41136efeea6e1426c631fa1ac0a221fe6978 | C9: Deep learning approach for Network Intrusion Detection in Software Defined Networking | D9: 2016-10-01 | E9: 2016 | F9: Conference; JournalArticle; Review | G9: Computer Science | H9: 47 | I9: 635 | K9: {"CorpusId": 15987982, "DBLP": "conf/wincom/TangMMZG16", "DOI": "10.1109/WINCOM.2016.7777224", "MAG": "2560162835"} | L9: 10.1109/wincom.2016.7777224 | M9: TRUE | N9: http://eprints.whiterose.ac.uk/106836/8/Tuan%20Tang_WINCOM16.pdf | O9: 258-263 | P9: 6 | R9: 20 | T9: 5; 17; 28; 25; 39 | U9: 22.8
A10: PRECISE | B10: 8e2527113c652a25dad5a8af72a67f2d0bbb2706 | C10: A Survey of Intrusion Detection Systems in Wireless Sensor Networks | D10: 2014-01-21 | E10: 2014 | F10: JournalArticle; Review | G10: Computer Science | H10: 41 | I10: 922 | K10: {"CorpusId": 14636557, "DBLP": "journals/comsur/ButunMS14", "DOI": "10.1109/SURV.2013.050113.00191", "MAG": "2011778831"} | L10: 10.1109/surv.2013.050113.00191 | M10: FALSE | O10: 266-282 | P10: 17 | R10: 73 | T10: 22; 23; 23 | U10: 22.66666666666667
A11: PRECISE | B11: 971766088dfaf63fb55e6f0190b14f28f2c98ad0 | C11: A Survey of Data Mining and Machine Learning Methods for Cyber Security Intrusion Detection | D11: 2016-01-22 | E11: 2016 | F11: JournalArticle; Review | G11: Computer Science | H11: 38 | I11: 1021 | K11: {"CorpusId": 206577177, "DBLP": "journals/comsur/BuczakG16", "DOI": "10.1109/COMST.2015.2494502", "MAG": "2342408547"} | L11: 10.1109/comst.2015.2494502 | M11: TRUE | N11: https://doi.org/10.1109/comst.2015.2494502 | O11: 1153-1176 | P11: 24 | R11: 110 | T11: 20; 6 | U11: 13
A12: PRECISE | B12: c9dbf8068d03b9ac6c5f02d40b75af182ca69699 | C12: A survey of intrusion detection techniques in Cloud | F12: JournalArticle; Review | G12: Computer Science | H12: 38 | I12: 918 | K12: {"CorpusId": 12815020, "DBLP": "journals/jnca/ModiPBPPR13", "DOI": "10.1016/j.jnca.2012.05.003", "MAG": "1489073918"} | L12: 10.1016/j.jnca.2012.05.003 | M12: TRUE | N12: https://openaccess.city.ac.uk/id/eprint/1737/1/A%20survey%20of%20intrusion%20detection%20techniques%20in%20Cloud.pdf | O12: 42-57 | P12: 16 | R12: 75 | T12: 21; 19; 10; 6; 8; 41 | U12: 17.5
A13: PRECISE | B13: 6bd85cfce9eeee059b1ee73851711e9ec847a31b | C13: The Evolution of MAC Protocols in Wireless Sensor Networks: A Survey | D13: 2013-01-21 | E13: 2013 | F13: JournalArticle; Review | G13: Computer Science | H13: 37 | I13: 602 | K13: {"CorpusId": 25576812, "DBLP": "journals/comsur/HuangXSMX13", "DOI": "10.1109/SURV.2012.040412.00105", "MAG": "2170044052"} | L13: 10.1109/surv.2012.040412.00105 | M13: FALSE | O13: 101-120 | P13: 20 | R13: 78 | T13: 14; 39; 5; 32; 42 | U13: 26.4
A14: PRECISE | B14: c42c29c793f3b8518a313d03fa101b1201a8ad14 | C14: Network intrusion detection system: A systematic study of machine learning and deep learning approaches | D14: 2020-10-16 | E14: 2020 | F14: JournalArticle; Review | G14: Computer Science | H14: 37 | I14: 832 | J14: The rapid advances in the internet and communication fields have resulted in a huge increase in the network size and the corresponding data. As a result, many novel attacks are being generated and have posed challenges for network security to accurately detect intrusions. Furthermore, the presence of the intruders with the aim to launch various attacks within the network cannot be ignored. An intrusion detection system (IDS) is one such tool that prevents the network from possible intrusions by inspecting the network traffic, to ensure its confidentiality, integrity, and availability. Despite enormous efforts by the researchers, IDS still faces challenges in improving detection accuracy while reducing false alarm rates and in detecting novel intrusions. Recently, machine learning (ML) and deep learning (DL)‐based IDS systems are being deployed as potential solutions to detect intrusions across the network in an efficient manner. This article first clarifies the concept of IDS and then provides the taxonomy based on the notable ML and DL techniques adopted in designing network‐based IDS (NIDS) systems. A comprehensive review of the recent NIDS‐based articles is provided by discussing the strengths and limitations of the proposed solutions. Then, recent trends and advancements of ML and DL‐based NIDS are provided in terms of the proposed methodology, evaluation metrics, and dataset selection. Using the shortcomings of the proposed methods, we highlighted various research challenges and provided the future scope for the research in improving ML and DL‐based NIDS. | K14: {"CorpusId": 225153435, "DBLP": "journals/ett/AhmadKSAA21", "DOI": "10.1002/ett.4150", "MAG": "3093410479"} | L14: 10.1002/ett.4150 | M14: TRUE | N14: https://onlinelibrary.wiley.com/doi/pdfdirect/10.1002/ett.4150 | R14: 150 | S14: 2020 | T14: 11; 16; 8; 14; 6 | U14: 11
A15: PRECISE | B15: 67f3df0846e89da5dfc7c25980d9189c7df50292 | C15: CoSDEO 2016 Keynote: A decade later — Challenges: Device-free passive localization for wireless environments | D15: 2016-03-14 | E15: 2016 | F15: Conference; JournalArticle; Review | G15: Computer Science | H15: 34 | I15: 417 | K15: {"CorpusId": 34643949, "DBLP": "conf/percom/Youssef16", "DOI": "10.1109/PERCOMW.2016.7457113", "MAG": "2337900948"} | L15: 10.1109/percomw.2016.7457113 | M15: FALSE | O15: 1-2 | P15: 2 | R15: 45 | T15: 43 | U15: 43
A16: PRECISE | B16: cbe3fda28a29052fb82dcaca66be1edf549180d4 | C16: A Survey of Network-based Intrusion Detection Data Sets | D16: 2019-03-06 | E16: 2019 | F16: JournalArticle; Review | G16: Computer Science | H16: 33 | I16: 586 | K16: {"ArXiv": "1903.02460", "CorpusId": 70349997, "DBLP": "journals/compsec/RingWSLH19", "DOI": "10.1016/j.cose.2019.06.005", "MAG": "2950955939"} | L16: 10.1016/j.cose.2019.06.005 | M16: TRUE | N16: http://arxiv.org/pdf/1903.02460 | O16: 147-167 | P16: 21 | R16: 101 | S16: 2019 | T16: 11; 5; 1; 19; 53 | U16: 17.8
A17: PRECISE | B17: 22b56df45e2ff1aafca278253c24c6abafd0d0c7 | C17: A survey of intrusion detection techniques for cyber-physical systems | D17: 2014-03-01 | E17: 2014 | F17: JournalArticle; Review | G17: Computer Science | H17: 30 | I17: 645 | K17: {"CorpusId": 207209718, "DBLP": "journals/csur/MitchellC13", "DOI": "10.1145/2542049", "MAG": "2161630727"} | L17: 10.1145/2542049 | M17: TRUE | N17: http://people.cs.vt.edu/~irchen/ps/Mitchell-CSUR14.pdf | O17: 1 - 29 | P17: 29 | R17: 95 | T17: 12; 46 | U17: 29
A18: PRECISE | B18: 236dfdeb4511754cf71ba220ac569b11973502cd | C18: Machine Learning and Deep Learning Methods for Intrusion Detection Systems: A Survey | D18: 2019-10-17 | E18: 2019 | F18: Review | G18: Engineering | H18: 30 | I18: 776 | J18: Networks play important roles in modern life, and cyber security has become a vital research area. An intrusion detection system (IDS) which is an important cyber security technique, monitors the state of software and hardware running in the network. Despite decades of development, existing IDSs still face challenges in improving the detection accuracy, reducing the false alarm rate and detecting unknown attacks. To solve the above problems, many researchers have focused on developing IDSs that capitalize on machine learning methods. Machine learning methods can automatically discover the essential differences between normal data and abnormal data with high accuracy. In addition, machine learning methods have strong generalizability, so they are also able to detect unknown attacks. Deep learning is a branch of machine learning, whose performance is remarkable and has become a research hotspot. This survey proposes a taxonomy of IDS that takes data objects as the main dimension to classify and summarize machine learning-based and deep learning-based IDS literature. We believe that this type of taxonomy framework is fit for cyber security researchers. The survey first clarifies the concept and taxonomy of IDSs. Then, the machine learning algorithms frequently used in IDSs, metrics, and benchmark datasets are introduced. Next, combined with the representative literature, we take the proposed taxonomic system as a baseline and explain how to solve key IDS issues with machine learning and deep learning techniques. Finally, challenges and future developments are discussed by reviewing recent representative studies. | K18: {"CorpusId": 208843362, "DOI": "10.3390/app9204396", "MAG": "2980576170"} | L18: 10.3390/app9204396 | M18: TRUE | N18: https://www.mdpi.com/2076-3417/9/20/4396/pdf?version=1571308126 | R18: 91 | S18: 2019 | T18: 8; 8 | U18: 8
A19: PRECISE | B19: cead00c7b3384653ce8013139a5d4543d96fcd07 | C19: Fault Injection Attacks on Cryptographic Devices: Theory, Practice, and Countermeasures | D19: 2012-04-05 | E19: 2012 | F19: JournalArticle; Review | G19: Computer Science; Engineering | H19: 30 | I19: 553 | K19: {"CorpusId": 1762526, "DBLP": "journals/pieee/BarenghiBKN12", "DOI": "10.1109/JPROC.2012.2188769", "MAG": "2085992264"} | L19: 10.1109/jproc.2012.2188769 | M19: TRUE | N19: http://euler.ecs.umass.edu/research/bbkn-IEEEP-2012.pdf | O19: 3056-3076 | P19: 21 | R19: 94 | T19: 26; 27; 44; 39 | U19: 34
A20: PRECISE | B20: 25cd96cc105927efa772f690426e955f080f72ff | C20: A Scheme for Generating a Dataset for Anomalous Activity Detection in IoT Networks | D20: 2020-05-13 | E20: 2020 | F20: Conference; JournalArticle; Review | G20: Computer Science | H20: 27 | I20: 218 | K20: {"CorpusId": 218539986, "DBLP": "conf/ai/UllahM20", "DOI": "10.1007/978-3-030-47358-7_52", "MAG": "3022604549"} | L20: 10.1007/978-3-030-47358-7_52 | M20: FALSE | O20: 508-520 | P20: 13 | R20: 15 | T20: 13; 38 | U20: 25.5
A21: PRECISE | B21: f4ba147e57beee5e57cc4548feb130cbe16c9192 | C21: Network Intrusion Detection for IoT Security Based on Learning Techniques | D21: 2019-01-30 | E21: 2019 | F21: JournalArticle; Review | G21: Computer Science | H21: 27 | I21: 666 | J21: Pervasive growth of Internet of Things (IoT) is visible across the globe. The 2016 Dyn cyberattack exposed the critical fault-lines among smart networks. Security of IoT has become a critical concern. The danger exposed by infested Internet-connected Things not only affects the security of IoT but also threatens the complete Internet eco-system which can possibly exploit the vulnerable Things (smart devices) deployed as botnets. Mirai malware compromised the video surveillance devices and paralyzed Internet via distributed denial of service attacks. In the recent past, security attack vectors have evolved bothways, in terms of complexity and diversity. Hence, to identify and prevent or detect novel attacks, it is important to analyze techniques in IoT context. This survey classifies the IoT security threats and challenges for IoT networks by evaluating existing defense techniques. Our main focus is on network intrusion detection systems (NIDSs); hence, this paper reviews existing NIDS implementation tools and datasets as well as free and open-source network sniffing software. Then, it surveys, analyzes, and compares state-of-the-art NIDS proposals in the IoT context in terms of architecture, detection methodologies, validation strategies, treated threats, and algorithm deployments. The review deals with both traditional and machine learning (ML) NIDS techniques and discusses future directions. In this survey, our focus is on IoT NIDS deployed via ML since learning algorithms have a good success rate in security and privacy. The survey provides a comprehensive review of NIDSs deploying different aspects of learning techniques for IoT, unlike other top surveys targeting the traditional systems. We believe that, this paper will be useful for academia and industry research, first, to identify IoT threats and challenges, second, to implement their own NIDS and finally to propose new smart techniques in IoT context considering IoT limitations. Moreover, the survey will enable security individuals differentiate IoT NIDS from traditional ones. | K21: {"CorpusId": 86720272, "DBLP": "journals/comsur/ChaabouniMZSF19", "DOI": "10.1109/COMST.2019.2896380", "MAG": "2911505293"} | L21: 10.1109/comst.2019.2896380 | M21: FALSE | O21: 2671-2701 | P21: 31 | R21: 134 | T21: 3; 21; 16; 3; 16 | U21: 11.8
A22: PRECISE | B22: 39361b3507c9f8b0a97780568b645f80a208d78a | C22: Machine Learning and Deep Learning Methods for Cybersecurity | D22: 2018-05-15 | E22: 2018 | F22: JournalArticle; Review | G22: Computer Science | H22: 26 | I22: 826 | J22: With the development of the Internet, cyber-attacks are changing rapidly and the cyber security situation is not optimistic. This survey report describes key literature surveys on machine learning (ML) and deep learning (DL) methods for network analysis of intrusion detection and provides a brief tutorial description of each ML/DL method. Papers representing each method were indexed, read, and summarized based on their temporal or thermal correlations. Because data are so important in ML/DL methods, we describe some of the commonly used network datasets used in ML/DL, discuss the challenges of using ML/DL for cybersecurity and provide suggestions for research directions. | K22: {"CorpusId": 49866160, "DBLP": "journals/access/XinK0CLZGHW18", "DOI": "10.1109/ACCESS.2018.2836950", "MAG": "2803881474"} | L22: 10.1109/access.2018.2836950 | M22: TRUE | N22: https://doi.org/10.1109/access.2018.2836950 | O22: 35365-35381 | P22: 17 | R22: 76 | S22: 2018 | T22: 7; 3; 15; 17; 5; 11; 6; 7; 2 | U22: 8.11111111111111
A23: PRECISE | B23: 6083bd8cdb810ce3d4f4bb9a004cac2a58b424eb | C23: Demystifying IoT Security: An Exhaustive Survey on IoT Vulnerabilities and a First Empirical Look on Internet-Scale IoT Exploitations | D23: 2019-04-11 | E23: 2019 | F23: JournalArticle; Review | G23: Computer Science | H23: 26 | I23: 592 | J23: The security issue impacting the Internet-of-Things (IoT) paradigm has recently attracted significant attention from the research community. To this end, several surveys were put forward addressing various IoT-centric topics, including intrusion detection systems, threat modeling, and emerging technologies. In contrast, in this paper, we exclusively focus on the ever-evolving IoT vulnerabilities. In this context, we initially provide a comprehensive classification of state-of-the-art surveys, which address various dimensions of the IoT paradigm. This aims at facilitating IoT research endeavors by amalgamating, comparing, and contrasting dispersed research contributions. Subsequently, we provide a unique taxonomy, which sheds the light on IoT vulnerabilities, their attack vectors, impacts on numerous security objectives, attacks which exploit such vulnerabilities, corresponding remediation methodologies and currently offered operational cyber security capabilities to infer and monitor such weaknesses. This aims at providing the reader with a multidimensional research perspective related to IoT vulnerabilities, including their technical details and consequences, which is postulated to be leveraged for remediation objectives. Additionally, motivated by the lack of empirical (and malicious) data related to the IoT paradigm, this paper also presents a first look on Internet-scale IoT exploitations by drawing upon more than 1.2 GB of macroscopic, passive measurements’ data. This aims at practically highlighting the severity of the IoT problem, while providing operational situational awareness capabilities, which undoubtedly would aid in the mitigation task, at large. Insightful findings, inferences and outcomes in addition to open challenges and research problems are also disclosed in this paper, which we hope would pave the way for future research endeavors addressing theoretical and empirical aspects related to the imperative topic of IoT security. | K23: {"CorpusId": 201741566, "DBLP": "journals/comsur/NeshenkoBCKG19", "DOI": "10.1109/COMST.2019.2910750", "MAG": "2969468102"} | L23: 10.1109/comst.2019.2910750 | M23: TRUE | N23: https://doi.org/10.1109/comst.2019.2910750 | O23: 2702-2733 | P23: 32 | R23: 206 | T23: 8; 30; 19; 56; 29 | U23: 28.4
A24: PRECISE | B24: cf003fbb1609c1457701cb7d698a5361be1d16b1 | C24: An intrusion detection and prevention system in cloud computing: A systematic review | F24: JournalArticle; Review | G24: Computer Science | H24: 24 | I24: 443 | K24: {"CorpusId": 34668439, "DBLP": "journals/jnca/PatelTBJ13", "DOI": "10.1016/j.jnca.2012.08.007", "MAG": "2139836766"} | L24: 10.1016/j.jnca.2012.08.007 | M24: FALSE | O24: 25-41 | P24: 17 | R24: 90 | T24: 22; 14; 14; 16 | U24: 16.5
A25: PRECISE | B25: 2313d55f4e7739de529e966521018c9043c3fe45 | C25: Survey on Misbehavior Detection in Cooperative Intelligent Transportation Systems | D25: 2016-10-21 | E25: 2016 | F25: JournalArticle; Review | G25: Computer Science | H25: 23 | I25: 218 | J25: Cooperative intelligent transportation systems (cITS) are a promising technology to enhance driving safety and efficiency. Vehicles communicate wirelessly with other vehicles and infrastructure, thereby creating a highly dynamic and heterogeneously managed ad-hoc network. It is these network properties that make it a challenging task to protect integrity of the data and guarantee its correctness. A major component is the problem that traditional security mechanisms like public key infrastructure (PKI)-based asymmetric cryptography only exclude outsider attackers that do not possess key material. However, because attackers can be insiders within the network (i.e., possess valid key material), this approach cannot detect all possible attacks. In this survey, we present misbehavior detection mechanisms that can detect such insider attacks based on attacker behavior and information analysis. In contrast to well-known intrusion detection for classical IT systems, these misbehavior detection mechanisms analyze information semantics to detect attacks, which aligns better with highly application-tailored communication protocols foreseen for cITS. In our survey, we provide an extensive introduction to the cITS ecosystem and discuss shortcomings of PKI-based security. We derive and discuss a classification for misbehavior detection mechanisms, provide an in-depth overview of seminal papers on the topic, and highlight open issues and possible future research trends. | K25: {"ArXiv": "1610.06810", "CorpusId": 8876979, "DBLP": "journals/comsur/HeijdenDLK19", "DOI": "10.1109/COMST.2018.2873088", "MAG": "2963030364"} | L25: 10.1109/comst.2018.2873088 | M25: TRUE | N25: https://arxiv.org/pdf/1610.06810 | O25: 779-811 | P25: 33 | R25: 138 | S25: 2016 | T25: 3; 15; 21; 47 | U25: 21.5
A26: PRECISE | B26: 4a8c332b09bb99333a8bce6a4640a20c1352aa63 | C26: A Survey on Security Threats and Defensive Techniques of Machine Learning: A Data Driven View | D26: 2018-02-13 | E26: 2018 | F26: JournalArticle; Review | G26: Computer Science | H26: 23 | I26: 357 | J26: Machine learning is one of the most prevailing techniques in computer science, and it has been widely applied in image processing, natural language processing, pattern recognition, cybersecurity, and other fields. Regardless of successful applications of machine learning algorithms in many scenarios, e.g., facial recognition, malware detection, automatic driving, and intrusion detection, these algorithms and corresponding training data are vulnerable to a variety of security threats, inducing a significant performance decrease. Hence, it is vital to call for further attention regarding security threats and corresponding defensive techniques of machine learning, which motivates a comprehensive survey in this paper. Until now, researchers from academia and industry have found out many security threats against a variety of learning algorithms, including naive Bayes, logistic regression, decision tree, support vector machine (SVM), principle component analysis, clustering, and prevailing deep neural networks. Thus, we revisit existing security threats and give a systematic survey on them from two aspects, the training phase and the testing/inferring phase. After that, we categorize current defensive techniques of machine learning into four groups: security assessment mechanisms, countermeasures in the training phase, those in the testing or inferring phase, data security, and privacy. Finally, we provide five notable trends in the research on security threats and defensive techniques of machine learning, which are worth doing in-depth studies in future. | K26: {"CorpusId": 4111957, "DBLP": "journals/access/LiuLZCYL18", "DOI": "10.1109/ACCESS.2018.2805680", "MAG": "2791319131"} | L26: 10.1109/access.2018.2805680 | M26: TRUE | N26: https://doi.org/10.1109/access.2018.2805680 | O26: 12103-12117 | P26: 15 | R26: 106 | S26: 2018 | T26: 20; 6; 13; 20; 56; 99 | U26: 35.66666666666666
A27: PRECISE | B27: 922b6fb164f5b9d774d16cb14c31f5cb68a02046 | C27: Game theory meets network security and privacy | D27: 2013-06-01 | E27: 2013 | F27: JournalArticle; Review | G27: Computer Science | H27: 23 | I27: 797 | K27: {"CorpusId": 207203993, "DBLP": "journals/csur/ManshaeiZABH13", "DOI": "10.1145/2480741.2480742", "MAG": "2067064328"} | L27: 10.1145/2480741.2480742 | M27: TRUE | N27: http://infoscience.epfl.ch/record/151965/files/Game%20Sec-ACM%20Survey.pdf | O27: 25:1-25:39 | R27: 136 | T27: 24; 51; 48; 96; 87 | U27: 61.2
A28: PRECISE | B28: de3ddfdb3c8c995cff057e010db6ac70e06ef5b5 | C28: Data stream clustering: A survey | D28: 2013-10-01 | E28: 2013 | F28: JournalArticle; Review | G28: Computer Science | H28: 23 | I28: 547 | K28: {"CorpusId": 3346652, "DBLP": "journals/csur/SilvaFBHCG13", "DOI": "10.1145/2522968.2522981", "MAG": "2088340225"} | L28: 10.1145/2522968.2522981 | M28: TRUE | N28: http://repositorio.inesctec.pt/bitstreams/5cd9346a-c309-4fdb-b2b2-20148318a05c/download | O28: 13:1-13:31 | R28: 134 | T28: 15; 10; 29; 33; 47; 61 | U28: 32.5
A29: PRECISE | B29: 246ba747471461dd30f8d3491d711c54ca515eb3 | C29: Routing Attacks and Mitigation Methods for RPL-Based Internet of Things | F29: JournalArticle; Review | G29: Computer Science | H29: 20 | I29: 188 | J29: The recent bloom of Internet of Things (IoT) and its prevalence in many security-sensitive environments made the security of these networks a crucial requirement. Routing in many of IoT networks has been performed using the routing protocol for low power and lossy networks (RPL), due to its energy-efficient mechanisms, secure modes availability, and its adaptivity to work in various environments; hence, RPL security has been the focus of many researchers. This paper presents a comprehensive study of RPL, its known attacks, and the mitigation methods proposed to counter these attacks. We conducted a detailed review of the RPL standard, including a recently proposed modification. Also, we investigated all recently published attacks on RPL and their mitigation methods through the literature. Based on this investigation, and to the best of our knowledge, we introduced a first-of-its-kind classification scheme for the mitigation methods that is based on the techniques used for the mitigation. Furthermore, we thoroughly discussed RPL-based intrusion detection systems (IDSs) and their classifications, highlighting the most recently proposed IDSs. | K29: {"CorpusId": 69422280, "DBLP": "journals/comsur/RaoofML19", "DOI": "10.1109/COMST.2018.2885894", "MAG": "2904959125"} | L29: 10.1109/comst.2018.2885894 | M29: FALSE | O29: 1582-1606 | P29: 25 | R29: 95 | T29: 7; 23; 35 | U29: 21.66666666666667
A30: PRECISE | B30: e11d5a4edec55f5d5dc8ea25621ecbf89e9bccb7 | C30: Taxonomy and Survey of Collaborative Intrusion Detection | D30: 2015-05-11 | E30: 2015 | F30: JournalArticle; Review | G30: Computer Science | H30: 20 | I30: 299 | K30: {"CorpusId": 207223163, "DBLP": "journals/csur/Vasilomanolakis15", "DOI": "10.1145/2716260", "MAG": "1772700132"} | L30: 10.1145/2716260 | M30: FALSE | O30: 1 - 33 | P30: 33 | R30: 93 | T30: 17; 17; 48; 18 | U30: 25
A31: PRECISE | B31: 36cf949aca4d0b93383ec2756717404b37ef3852 | C31: A Survey of MANET Intrusion Detection & Prevention Approaches for Network Layer Attacks | D31: 2013-03-28 | E31: 2013 | F31: JournalArticle; Review | G31: Computer Science | H31: 19 | I31: 263 | K31: {"CorpusId": 18189153, "DBLP": "journals/comsur/NadeemH13", "DOI": "10.1109/SURV.2013.030713.00201", "MAG": "2036584242"} | L31: 10.1109/surv.2013.030713.00201 | M31: TRUE | N31: https://openresearch.surrey.ac.uk/view/delivery/44SUR_INST/12139983090002346/13140370410002346 | O31: 2027-2045 | P31: 19 | R31: 98 | T31: 17; 19 | U31: 18
A32: PRECISE | B32: 6edf7ed0e68bcf98ebcb600343c1e08f27c1c62f | C32: Deep Learning for Encrypted Traffic Classification: An Overview | D32: 2018-10-18 | E32: 2018 | F32: JournalArticle; Review | G32: Computer Science | H32: 19 | I32: 435 | J32: Traffic classification has been studied for two decades and applied to a wide range of applications from QoS provisioning and billing in ISPs to security-related applications in firewalls and intrusion detection systems. Port-based, data packet inspection, and classical machine learning methods have been used extensively in the past, but their accuracy has declined due to the dramatic changes in Internet traffic, particularly the increase in encrypted traffic. With the proliferation of deep learning methods, researchers have recently investigated these methods for traffic classification and reported high accuracy. In this article, we introduce a general framework for deep-learning-based traffic classification. We present commonly used deep learning methods and their application in traffic classification tasks. Then we discuss open problems, challenges, and opportunities for traffic classification. | K32: {"ArXiv": "1810.07906", "CorpusId": 53016938, "DBLP": "journals/corr/abs-1810-07906", "DOI": "10.1109/MCOM.2019.1800819", "MAG": "2897202622"} | L32: 10.1109/mcom.2019.1800819 | M32: TRUE | N32: https://arxiv.org/pdf/1810.07906 | O32: 76-81 | P32: 6 | R32: 21 | S32: 2018 | T32: 10; 9 | U32: 9.5
A33: PRECISE | B33: d3703f5faf73869110dea101109f60b4c1566c76 | C33: A Survey on Industrial Control System Testbeds and Datasets for Security Research | D33: 2021-02-10 | E33: 2021 | F33: JournalArticle; Review | G33: Computer Science | H33: 19 | I33: 154 | J33: The increasing digitization and interconnection of legacy Industrial Control Systems (ICSs) open new vulnerability surfaces, exposing such systems to malicious attackers. Furthermore, since ICSs are often employed in critical infrastructures (e.g., nuclear plants) and manufacturing companies (e.g., chemical industries), attacks can lead to devastating physical damages. In dealing with this security requirement, the research community focuses on developing new security mechanisms such as Intrusion Detection Systems (IDSs), facilitated by leveraging modern machine learning techniques. However, these algorithms require a testing platform and a considerable amount of data to be trained and tested accurately. To satisfy this prerequisite, Academia, Industry, and Government are increasingly proposing testbed (i.e., scaled-down versions of ICSs or simulations) to test the performances of the IDSs. Furthermore, to enable researchers to cross-validate security systems (e.g., security-by-design concepts or anomaly detectors), several datasets have been collected from testbeds and shared with the community. In this paper, we provide a deep and comprehensive overview of ICSs, presenting the architecture design, the employed devices, and the security protocols implemented. We then collect, compare, and describe testbeds and datasets in the literature, highlighting key challenges and design guidelines to keep in mind in the design phases. Furthermore, we enrich our work by reporting the best performing IDS algorithms tested on every dataset to create a baseline in state of the art for this field. Finally, driven by knowledge accumulated during this survey’s development, we report advice and good practices on the development, the choice, and the utilization of testbeds, datasets, and IDSs. | K33: {"ArXiv": "2102.05631", "CorpusId": 231861910, "DBLP": "journals/corr/abs-2102-05631", "DOI": "10.1109/COMST.2021.3094360"} | L33: 10.1109/comst.2021.3094360 | M33: TRUE | N33: https://arxiv.org/pdf/2102.05631 | O33: 2248-2294 | P33: 47 | R33: 234 | S33: 2020 | T33: 73; 6; 10 | U33: 29.66666666666667
A34: PRECISE | B34: 3ef1e8599ea27cafb9ccbc44619ce18729a86801 | C34: Toward Proactive, Adaptive Defense: A Survey on Moving Target Defense | D34: 2019-09-12 | E34: 2019 | F34: JournalArticle; Review | G34: Computer Science | H34: 17 | I34: 237 | J34: Reactive defense mechanisms, such as intrusion detection systems, have made significant efforts to secure a system or network for the last several decades. However, the nature of reactive security mechanisms has limitations because potential attackers cannot be prevented in advance. We are facing a reality with the proliferation of persistent, advanced, intelligent attacks while defenders are often way behind attackers in taking appropriate actions to thwart potential attackers. The concept of moving target defense (MTD) has emerged as a proactive defense mechanism aiming to prevent attacks. In this work, we conducted a comprehensive, in-depth survey to discuss the following aspects of MTD: key roles, design principles, classifications, common attacks, key methodologies, important algorithms, metrics, evaluation methods, and application domains. We discuss the pros and cons of all aspects of MTD surveyed in this work. Lastly, we highlight insights and lessons learned from this study and suggest future work directions. The aim of this paper is to provide the overall trends of MTD research in terms of critical aspects of defense systems for researchers who seek to develop proactive, adaptive MTD mechanisms. | K34: {"ArXiv": "1909.08092", "CorpusId": 202660686, "DBLP": "journals/corr/abs-1909-08092", "DOI": "10.1109/COMST.2019.2963791", "MAG": "2996903041"} | L34: 10.1109/comst.2019.2963791 | M34: TRUE | N34: http://arxiv.org/pdf/1909.08092 | O34: 709-745 | P34: 37 | R34: 195 | S34: 2019 | T34: 32; 6; 12; 10; 16; 18; 35; 27; 3 | U34: 17.66666666666667
A35: PRECISE | B35: 8b6e8d71d17a1fb5a7172c5d44ebba1cf06a7dd4 | C35: Shallow and Deep Networks Intrusion Detection System: A Taxonomy and Survey | D35: 2017-01-09 | E35: 2017 | F35: JournalArticle; Review | G35: Computer Science | H35: 17 | I35: 239 | J35: Intrusion detection has attracted a considerable interest from researchers and industries. The community, after many years of research, still faces the problem of building reliable and efficient IDS that are capable of handling large quantities of data, with changing patterns in real time situations. The work presented in this manuscript classifies intrusion detection systems (IDS). Moreover, a taxonomy and survey of shallow and deep networks intrusion detection systems is presented based on previous and current works. This taxonomy and survey reviews machine learning techniques and their performance in detecting anomalies. Feature selection which influences the effectiveness of machine learning (ML) IDS is discussed to explain the role of feature selection in the classification and training phase of ML IDS. Finally, a discussion of the false and true positive alarm rates is presented to help researchers model reliable and efficient machine learning based intrusion detection systems. | K35: {"ArXiv": "1701.02145", "CorpusId": 11381530, "DBLP": "journals/corr/HodoBHTA17", "MAG": "2576897537"} | M35: FALSE | R35: 157 | S35: 2016 | T35: 4; 19; 9; 22; 16 | U35: 14
A36: PRECISE | B36: a9b901fcd68a3715d5ef186a398476bc1e762b0e | C36: Deep Reinforcement Learning for Cyber Security | D36: 2019-06-13 | E36: 2019 | F36: JournalArticle; Review | G36: Computer Science; Mathematics; Medicine | H36: 16 | I36: 360 | J36: The scale of Internet-connected systems has increased considerably, and these systems are being exposed to cyberattacks more than ever. The complexity and dynamics of cyberattacks require protecting mechanisms to be responsive, adaptive, and scalable. Machine learning, or more specifically deep reinforcement learning (DRL), methods have been proposed widely to address these issues. By incorporating deep learning into traditional RL, DRL is highly capable of solving complex, dynamic, and especially high-dimensional cyber defense problems. This article presents a survey of DRL approaches developed for cyber security. We touch on different vital aspects, including DRL-based security methods for cyber–physical systems, autonomous intrusion detection techniques, and multiagent DRL-based game theory simulations for defense strategies against cyberattacks. Extensive discussions and future research directions on DRL-based cyber security are also given. We expect that this comprehensive review provides the foundations for and facilitates future studies on exploring the potential of emerging DRL to cope with increasingly complex cyber security problems. | K36: {"ArXiv": "1906.05799", "CorpusId": 189762438, "DBLP": "journals/corr/abs-1906-05799", "DOI": "10.1109/TNNLS.2021.3121870", "MAG": "2952298682", "PubMed": "34723814"} | L36: 10.1109/tnnls.2021.3121870 | M36: TRUE | N36: https://arxiv.org/pdf/1906.05799 | O36: 3779-3795 | P36: 17 | R36: 217 | S36: 2019 | T36: 30; 44 | U36: 37
A37: PRECISE | B37: be71e47e3247d60398d5a8dfa7d343dc4a7c27d1 | C37: Security aspects of the in-vehicle network in the connected car | D37: 2011-06-05 | E37: 2011 | F37: JournalArticle; Review | G37: Computer Science; Engineering | H37: 16 | I37: 244 | K37: {"CorpusId": 5900712, "DBLP": "conf/ivs/KlebergerOJ11", "DOI": "10.1109/IVS.2011.5940525", "MAG": "2096279841"} | L37: 10.1109/ivs.2011.5940525 | M37: FALSE | O37: 528-533 | P37: 6 | R37: 34 | T37: 7; 18; 25 | U37: 16.66666666666667
A38: PRECISE | B38: 13f5588e5a745e15e4176fd6c47c8f5befc19605 | C38: Intrusion detection and Big Heterogeneous Data: a Survey | D38: 2015-02-27 | E38: 2015 | F38: JournalArticle; Review | G38: Computer Science | H38: 15 | I38: 294 | J38: Intrusion Detection has been heavily studied in both industry and academia, but cybersecurity analysts still desire much more alert accuracy and overall threat analysis in order to secure their systems within cyberspace. Improvements to Intrusion Detection could be achieved by embracing a more comprehensive approach in monitoring security events from many different heterogeneous sources. Correlating security events from heterogeneous sources can grant a more holistic view and greater situational awareness of cyber threats. One problem with this approach is that currently, even a single event source (e.g., network traffic) can experience Big Data challenges when considered alone. Attempts to use more heterogeneous data sources pose an even greater Big Data challenge. Big Data technologies for Intrusion Detection can help solve these Big Heterogeneous Data challenges. In this paper, we review the scope of works considering the problem of heterogeneous data and in particular Big Heterogeneous Data. We discuss the specific issues of Data Fusion, Heterogeneous Intrusion Detection Architectures, and Security Information and Event Management (SIEM) systems, as well as presenting areas where more research opportunities exist. Overall, both cyber threat analysis and cyber intelligence could be enhanced by correlating security events across many diverse heterogeneous sources. | K38: {"CorpusId": 12595430, "DBLP": "journals/jbd/ZuechKW15", "DOI": "10.1186/s40537-015-0013-4", "MAG": "2108142795"} | L38: 10.1186/s40537-015-0013-4 | M38: TRUE | N38: https://journalofbigdata.springeropen.com/counter/pdf/10.1186/s40537-015-0013-4 | O38: 1-41 | P38: 41 | R38: 86 | S38: 2015 | T38: 8; 80; 22 | U38: 36.66666666666666
A39: PRECISE | B39: 260a8c49efed69f969327f4151237a38e184270b | C39: A Review of Intrusion Detection Systems Using Machine and Deep Learning in Internet of Things: Challenges, Solutions and Future Directions | D39: 2020-07-20 | E39: 2020 | F39: Review | G39: Computer Science | H39: 15 | I39: 237 | J39: The Internet of Things (IoT) is poised to impact several aspects of our lives with its fast proliferation in many areas such as wearable devices, smart sensors and home appliances. IoT devices are characterized by their connectivity, pervasiveness and limited processing capability. The number of IoT devices in the world is increasing rapidly and it is expected that there will be 50 billion devices connected to the Internet by the end of the year 2020. This explosion of IoT devices, which can be easily increased compared to desktop computers, has led to a spike in IoT-based cyber-attack incidents. To alleviate this challenge, there is a requirement to develop new techniques for detecting attacks initiated from compromised IoT devices. Machine and deep learning techniques are in this context the most appropriate detective control approach against attacks generated from IoT devices. This study aims to present a comprehensive review of IoT systems-related technologies, protocols, architecture and threats emerging from compromised IoT devices along with providing an overview of intrusion detection models. This work also covers the analysis of various machine learning and deep learning-based techniques suitable to detect IoT systems related to cyber-attacks. | K39: {"CorpusId": 225563015, "DOI": "10.3390/electronics9071177", "MAG": "3043799819"} | L39: 10.3390/electronics9071177 | M39: TRUE | N39: https://www.mdpi.com/2079-9292/9/7/1177/pdf | R39: 213 | S39: 2020 | T39: 1; 50; 4; 13; 12; 4 | U39: 14
A40: PRECISE | B40: 0fd2596df662912e293ff5efb21392581ecf0d65 | C40: On the Vital Areas of Intrusion Detection Systems in Wireless Sensor Networks | D40: 2013-01-09 | E40: 2013 | F40: JournalArticle; Review | G40: Computer Science | H40: 14 | I40: 230 | K40: {"CorpusId": 7170677, "DBLP": "journals/comsur/AbduvaliyevPZRW13", "DOI": "10.1109/SURV.2012.121912.00006", "MAG": "2121720842"} | L40: 10.1109/surv.2012.121912.00006 | M40: FALSE | O40: 1223-1237 | P40: 15 | R40: 101 | T40: 2; 30; 52; 30; 24 | U40: 27.6
...

Sheet Metrics (computed)
A1: cites_per_day | B1: recency_delay_years | C1: pages_minus_refs | D1: normalized_pages_minus_refs | E1: normalized_references_count | F1: normalized_recency_delay | G1: normalized_cites_per_day | H1: normalized_mean_author_hindex | I1: composite_score
A2: {=IF(LEN(rawdata!B2:B14026)=0, "", IFERROR( VALUE(rawdata!I2:I14026) / IF( (TODAY() - DATEVALUE(rawdata!D2:D14026)) < 1, 1, (TODAY() - DATEVALUE(rawdata!D2:D14026)) ), "" ) )} -> 0.47235693 | B2: {=IF(LEN(rawdata!B2:B14026)=0, "", IF( (LEN(rawdata!E2:E14026)=0) + (LEN(rawdata!S2:S14026)=0), "", IF( (VALUE(rawdata!E2:E14026) - VALUE(rawdata!S2:S14026)) < 0, 0, VALUE(rawdata!E2:E14026) - VALUE(rawdata!S2:S14026) ) ) )} | C2: {=IF(LEN(rawdata!B2:B14026)=0, "", IF( (LEN(rawdata!P2:P14026)=0) + (LEN(rawdata!Q2:Q14026)=0), "", IFERROR(VALUE(rawdata!P2:P14026),"") - IFERROR(VALUE(rawdata!Q2:Q14026),"") ) )} | D2: =IFERROR(__xludf.DUMMYFUNCTION("ARRAYFORMULA( IF(LEN(rawdata!B2:B14026)=0, """", IF(LEN(C2:C14026)=0, """", IF( PERCENTILE( FILTER(IFERROR(VALUE(C2:C14026),), ISNUMBER(IFERROR(VALUE(C2:C14026),))), 0.05 ) = PERCENTILE( FILTER(IFERROR(VALUE(C2:C14026),), ISNU"&"MBER(IFERROR(VALUE(C2:C14026),))), 0.95 ), 1, IF( ( (IFERROR(VALUE(#REF!),) - PERCENTILE(FILTER(IFERROR(VALUE(#REF!),), ISNUMBER(IFERROR(VALUE(#REF!),))), 0.05)) / ( PERCENTILE(FILTER(IFERROR(VALUE(#REF!),), ISNUMBER(IFERRO"&"R(VALUE(#REF!),))), 0.95) - PERCENTILE(FILTER(IFERROR(VALUE(#REF!),), ISNUMBER(IFERROR(VALUE(#REF!),))), 0.05) ) ) < 0, 0, IF( ( (IFERROR(VALUE(#REF!),) - PERCENTILE(FILTER(IFERROR(VALUE(#REF!),), ISNUMBER(IFERROR(VALUE(#REF!),))"&"), 0.05)) / ( PERCENTILE(FILTER(IFERROR(VALUE(#REF!),), ISNUMBER(IFERROR(VALUE(#REF!),))), 0.95) - PERCENTILE(FILTER(IFERROR(VALUE(#REF!),), ISNUMBER(IFERROR(VALUE(#REF!),))), 0.05) ) ) > 1, 1, ( (IFERROR(VALUE(#REF!),) -"&" PERCENTILE(FILTER(IFERROR(VALUE(#REF!),), ISNUMBER(IFERROR(VALUE(#REF!),))), 0.05)) / ( PERCENTILE(FILTER(IFERROR(VALUE(#REF!),), ISNUMBER(IFERROR(VALUE(#REF!),))), 0.95) - PERCENTILE(FILTER(IFERROR(VALUE(#REF!),), ISNUMBER(IFERROR(VALUE(#REF!)"&",))), 0.05) ) ) ) ) ) ) ) )"),"") | E2: =IFERROR(__xludf.DUMMYFUNCTION("ARRAYFORMULA( IF(LEN(rawdata!B2:B14026)=0, """", IF(LEN(rawdata!R2:R14026)=0, """", IF( PERCENTILE( LN(1+FILTER(IFERROR(VALUE(rawdata!R2:R14026),), ISNUMBER(IFERROR(VALUE(rawdata!R2:R14026),)))), 0.05 ) = PERCENTILE( LN(1+FILT"&"ER(IFERROR(VALUE(rawdata!R2:R14026),), ISNUMBER(IFERROR(VALUE(rawdata!R2:R14026),)))), 0.95 ), 1, IF( ( ( LN(1+IFERROR(VALUE(rawdata!R2:R14026),)) - PERCENTILE(LN(1+FILTER(IFERROR(VALUE(rawdata!R2:R14026),), ISNUMBER(IFERRO"&"R(VALUE(rawdata!R2:R14026),)))), 0.05) ) / ( PERCENTILE(LN(1+FILTER(IFERROR(VALUE(rawdata!R2:R14026),), ISNUMBER(IFERROR(VALUE(rawdata!R2:R14026),)))), 0.95) - PERCENTILE(LN(1+FILTER(IFERROR(VALUE(rawdata!R2:R14026),), ISNUMBER(IFERROR(VALUE(rawda"&"ta!R2:R14026),)))), 0.05) ) ) < 0, 0, IF( ( ( LN(1+IFERROR(VALUE(rawdata!R2:R14026),)) - PERCENTILE(LN(1+FILTER(IFERROR(VALUE(rawdata!R2:R14026),), ISNUMBER(IFERROR(VALUE(rawdata!R2:R14026),)))), 0.05) ) / ( P"&"ERCENTILE(LN(1+FILTER(IFERROR(VALUE(rawdata!R2:R14026),), ISNUMBER(IFERROR(VALUE(rawdata!R2:R14026),)))), 0.95) - PERCENTILE(LN(1+FILTER(IFERROR(VALUE(rawdata!R2:R14026),), ISNUMBER(IFERROR(VALUE(rawdata!R2:R14026),)))), 0.05) ) ) > 1, 1, "&" ( ( LN(1+IFERROR(VALUE(rawdata!R2:R14026),)) - PERCENTILE(LN(1+FILTER(IFERROR(VALUE(rawdata!R2:R14026),), ISNUMBER(IFERROR(VALUE(rawdata!R2:R14026),)))), 0.05) ) / ( PERCENTILE(LN(1+FILTER(IFERROR(VALUE(rawdata!R2:R14026),), ISNUMBER(IFE"&"RROR(VALUE(rawdata!R2:R14026),)))), 0.95) - PERCENTILE(LN(1+FILTER(IFERROR(VALUE(rawdata!R2:R14026),), ISNUMBER(IFERROR(VALUE(rawdata!R2:R14026),)))), 0.05) ) ) ) ) ) ) ) )"),0.07976197121590477) -> 0.079761971 | F2: =IFERROR(__xludf.DUMMYFUNCTION("ARRAYFORMULA( IF(LEN(rawdata!B2:B14026)=0, """", IF(LEN(B2:B14026)=0, """", IF( PERCENTILE(FILTER(IFERROR(VALUE(B2:B14026),), ISNUMBER(IFERROR(VALUE(B2:B14026),))), 0.05) = PERCENTILE(FILTER(IFERROR(VALUE(B2:B14026),), ISNUMBER(IFERROR(VALUE(B2"&":B14026),))), 0.95), 1, 1 - IF( ((IFERROR(VALUE(B2:B14026),) - PERCENTILE(FILTER(IFERROR(VALUE(B2:B14026),), ISNUMBER(IFERROR(VALUE(B2:B14026),))), 0.05)) / (PERCENTILE(FILTER(IFERROR(VALUE(B2:B14026),), ISNUMBER(IFERROR(VALUE(B2:B140"&"26),))), 0.95) - PERCENTILE(FILTER(IFERROR(VALUE(B2:B14026),), ISNUMBER(IFERROR(VALUE(B2:B14026),))), 0.05)) ) < 0, 0, IF( ((IFERROR(VALUE(#REF!),) - PERCENTILE(FILTER(IFERROR(VALUE(#REF!),), ISNUMBER(IFERROR(VALUE(#REF!)"&",))), 0.05)) / (PERCENTILE(FILTER(IFERROR(VALUE(#REF!),), ISNUMBER(IFERROR(VALUE(#REF!),))), 0.95) - PERCENTILE(FILTER(IFERROR(VALUE(#REF!),), ISNUMBER(IFERROR(VALUE(#REF!),))), 0.05)) ) > 1, 1, ((IFERROR(VALUE(#"&"REF!),) - PERCENTILE(FILTER(IFERROR(VALUE(#REF!),), ISNUMBER(IFERROR(VALUE(#REF!),))), 0.05)) / (PERCENTILE(FILTER(IFERROR(VALUE(#REF!),), ISNUMBER(IFERROR(VALUE(#REF!),))), 0.95) - PERCENTILE(FILTER(IFERROR(VALUE(#REF!),), ISNUMBER(IFE"&"RROR(VALUE(#REF!),))), 0.05)) ) ) ) ) ) ) )"),"") | G2: =IFERROR(__xludf.DUMMYFUNCTION("ARRAYFORMULA( IF(LEN(rawdata!B2:B14026)=0, """", IF(LEN(A2:A14026)=0, """", IF( PERCENTILE(FILTER(IFERROR(VALUE(A2:A14026),), ISNUMBER(IFERROR(VALUE(A2:A14026),))), 0.05) = PERCENTILE(FILTER(IFERROR(VALUE(A2:A14026),), ISNUMBER(IFERROR(VALUE(A2"&":A14026),))), 0.95), 1, IF( ((IFERROR(VALUE(A2:A14026),) - PERCENTILE(FILTER(IFERROR(VALUE(A2:A14026),), ISNUMBER(IFERROR(VALUE(A2:A14026),))), 0.05)) / (PERCENTILE(FILTER(IFERROR(VALUE(A2:A14026),), ISNUMBER(IFERROR(VALUE(A2:A14026),"&"))), 0.95) - PERCENTILE(FILTER(IFERROR(VALUE(A2:A14026),), ISNUMBER(IFERROR(VALUE(A2:A14026),))), 0.05)) ) < 0, 0, IF( ((IFERROR(VALUE(#REF!),) - PERCENTILE(FILTER(IFERROR(VALUE(#REF!),), ISNUMBER(IFERROR(VALUE(#REF!),)))"&", 0.05)) / (PERCENTILE(FILTER(IFERROR(VALUE(#REF!),), ISNUMBER(IFERROR(VALUE(#REF!),))), 0.95) - PERCENTILE(FILTER(IFERROR(VALUE(#REF!),), ISNUMBER(IFERROR(VALUE(#REF!),))), 0.05)) ) > 1, 1, ((IFERROR(VALUE(#REF!"&"),) - PERCENTILE(FILTER(IFERROR(VALUE(#REF!),), ISNUMBER(IFERROR(VALUE(#REF!),))), 0.05)) / (PERCENTILE(FILTER(IFERROR(VALUE(#REF!),), ISNUMBER(IFERROR(VALUE(#REF!),))), 0.95) - PERCENTILE(FILTER(IFERROR(VALUE(#REF!),), ISNUMBER(IFERROR"&"(VALUE(#REF!),))), 0.05)) ) ) ) ) ) ) )"),1.0) -> 1 | H2: =IFERROR(__xludf.DUMMYFUNCTION("ARRAYFORMULA( IF(LEN(rawdata!B2:B14026)=0, """", IF(LEN(rawdata!U2:U14026)=0, """", IF( PERCENTILE(LN(1+FILTER(IFERROR(VALUE(rawdata!U2:U14026),), ISNUMBER(IFERROR(VALUE(rawdata!U2:U14026),)))), 0.05) = PERCENTILE(LN(1+FILTER(IFERROR(VALUE(rawd"&"ata!U2:U14026),), ISNUMBER(IFERROR(VALUE(rawdata!U2:U14026),)))), 0.95), 1, IF( ((LN(1+IFERROR(VALUE(rawdata!U2:U14026),)) - PERCENTILE(LN(1+FILTER(IFERROR(VALUE(rawdata!U2:U14026),), ISNUMBER(IFERROR(VALUE(rawdata!U2:U14026),)))), 0.05)) / "&" (PERCENTILE(LN(1+FILTER(IFERROR(VALUE(rawdata!U2:U14026),), ISNUMBER(IFERROR(VALUE(rawdata!U2:U14026),)))), 0.95) - PERCENTILE(LN(1+FILTER(IFERROR(VALUE(rawdata!U2:U14026),), ISNUMBER(IFERROR(VALUE(rawdata!U2:U14026),)))), 0.05)) ) < "&"0, 0, IF( ((LN(1+IFERROR(VALUE(rawdata!U2:U14026),)) - PERCENTILE(LN(1+FILTER(IFERROR(VALUE(rawdata!U2:U14026),), ISNUMBER(IFERROR(VALUE(rawdata!U2:U14026),)))), 0.05)) / (PERCENTILE(LN(1+FILTER(IFERROR(VALUE(rawdata!U2:U14026"&"),), ISNUMBER(IFERROR(VALUE(rawdata!U2:U14026),)))), 0.95) - PERCENTILE(LN(1+FILTER(IFERROR(VALUE(rawdata!U2:U14026),), ISNUMBER(IFERROR(VALUE(rawdata!U2:U14026),)))), 0.05)) ) > 1, 1, ((LN(1+IFERROR(VALUE(rawdata!U2:U140"&"26),)) - PERCENTILE(LN(1+FILTER(IFERROR(VALUE(rawdata!U2:U14026),), ISNUMBER(IFERROR(VALUE(rawdata!U2:U14026),)))), 0.05)) / (PERCENTILE(LN(1+FILTER(IFERROR(VALUE(rawdata!U2:U14026),), ISNUMBER(IFERROR(VALUE(rawdata!U2:U14026),)))), 0.95) - "&" PERCENTILE(LN(1+FILTER(IFERROR(VALUE(rawdata!U2:U14026),), ISNUMBER(IFERROR(VALUE(rawdata!U2:U14026),)))), 0.05)) ) ) ) ) ) ) )"),0.0) -> 0 | I2: {=IF(LEN(rawdata!B2:B14026)=0, "", 0.3*D2:D14026 + 0.25*E2:E14026 + 0.2*F2:F14026 + 0.15*G2:G14026 + 0.1*H2:H14026 )} -> 0.16994049
A3: 0.20431211 | D3: =IFERROR(__xludf.DUMMYFUNCTION("""COMPUTED_VALUE"""),"") | E3: =IFERROR(__xludf.DUMMYFUNCTION("""COMPUTED_VALUE"""),0.9548721026215339) -> 0.9548721 | F3: =IFERROR(__xludf.DUMMYFUNCTION("""COMPUTED_VALUE"""),"") | G3: =IFERROR(__xludf.DUMMYFUNCTION("""COMPUTED_VALUE"""),1.0) -> 1 | H3: =IFERROR(__xludf.DUMMYFUNCTION("""COMPUTED_VALUE"""),0.8059258159859609) -> 0.80592582 | I3: 0.46931061
A4: 0.28599562 | D4: =IFERROR(__xludf.DUMMYFUNCTION("""COMPUTED_VALUE"""),"") | E4: =IFERROR(__xludf.DUMMYFUNCTION("""COMPUTED_VALUE"""),0.882367679076927) -> 0.88236768 | F4: =IFERROR(__xludf.DUMMYFUNCTION("""COMPUTED_VALUE"""),"") | G4: =IFERROR(__xludf.DUMMYFUNCTION("""COMPUTED_VALUE"""),1.0) -> 1 | H4: =IFERROR(__xludf.DUMMYFUNCTION("""COMPUTED_VALUE"""),0.7699084914494659) -> 0.76990849 | I4: 0.44758277
D5: =IFERROR(__xludf.DUMMYFUNCTION("""COMPUTED_VALUE"""),"") | E5: =IFERROR(__xludf.DUMMYFUNCTION("""COMPUTED_VALUE"""),0.6297361753994164) -> 0.62973618 | F5: =IFERROR(__xludf.DUMMYFUNCTION("""COMPUTED_VALUE"""),"") | G5: =IFERROR(__xludf.DUMMYFUNCTION("""COMPUTED_VALUE"""),"") | H5: =IFERROR(__xludf.DUMMYFUNCTION("""COMPUTED_VALUE"""),0.20085468356535413) -> 0.20085468 | I5: 0.17751951
A6: 0.27721845 | D6: =IFERROR(__xludf.DUMMYFUNCTION("""COMPUTED_VALUE"""),"") | E6: =IFERROR(__xludf.DUMMYFUNCTION("""COMPUTED_VALUE"""),1.0) -> 1 | F6: =IFERROR(__xludf.DUMMYFUNCTION("""COMPUTED_VALUE"""),"") | G6: =IFERROR(__xludf.DUMMYFUNCTION("""COMPUTED_VALUE"""),1.0) -> 1 | H6: =IFERROR(__xludf.DUMMYFUNCTION("""COMPUTED_VALUE"""),0.87183090148872) -> 0.8718309 | I6: 0.48718309
A7: 0.56348511 | B7: 1 | D7: =IFERROR(__xludf.DUMMYFUNCTION("""COMPUTED_VALUE"""),"") | E7: =IFERROR(__xludf.DUMMYFUNCTION("""COMPUTED_VALUE"""),0.823149971850111) -> 0.82314997 | F7: =IFERROR(__xludf.DUMMYFUNCTION("""COMPUTED_VALUE"""),1.0) -> 1 | G7: =IFERROR(__xludf.DUMMYFUNCTION("""COMPUTED_VALUE"""),1.0) -> 1 | H7: =IFERROR(__xludf.DUMMYFUNCTION("""COMPUTED_VALUE"""),0.7545924021819583) -> 0.7545924 | I7: 0.63124673
A8: 0.28825623 | D8: =IFERROR(__xludf.DUMMYFUNCTION("""COMPUTED_VALUE"""),"") | E8: =IFERROR(__xludf.DUMMYFUNCTION("""COMPUTED_VALUE"""),0.7118469843264902) -> 0.71184698 | F8: =IFERROR(__xludf.DUMMYFUNCTION("""COMPUTED_VALUE"""),"") | G8: =IFERROR(__xludf.DUMMYFUNCTION("""COMPUTED_VALUE"""),1.0) -> 1 | H8: =IFERROR(__xludf.DUMMYFUNCTION("""COMPUTED_VALUE"""),0.30345515853674393) -> 0.30345516 | I8: 0.35830726
A9: 0.19318528 | D9: =IFERROR(__xludf.DUMMYFUNCTION("""COMPUTED_VALUE"""),"") | E9: =IFERROR(__xludf.DUMMYFUNCTION("""COMPUTED_VALUE"""),0.19773288331254052) -> 0.19773288 | F9: =IFERROR(__xludf.DUMMYFUNCTION("""COMPUTED_VALUE"""),"") | G9: =IFERROR(__xludf.DUMMYFUNCTION("""COMPUTED_VALUE"""),1.0) -> 1 | H9: =IFERROR(__xludf.DUMMYFUNCTION("""COMPUTED_VALUE"""),0.701464288130925) -> 0.70146429 | I9: 0.26957965
A10: 0.2158745 | D10: =IFERROR(__xludf.DUMMYFUNCTION("""COMPUTED_VALUE"""),"") | E10: =IFERROR(__xludf.DUMMYFUNCTION("""COMPUTED_VALUE"""),0.6393425607818837) -> 0.63934256 | F10: =IFERROR(__xludf.DUMMYFUNCTION("""COMPUTED_VALUE"""),"") | G10: =IFERROR(__xludf.DUMMYFUNCTION("""COMPUTED_VALUE"""),1.0) -> 1 | H10: =IFERROR(__xludf.DUMMYFUNCTION("""COMPUTED_VALUE"""),0.6990982929283924) -> 0.69909829 | I10: 0.37974547
A11: 0.28841808 | D11: =IFERROR(__xludf.DUMMYFUNCTION("""COMPUTED_VALUE"""),"") | E11: =IFERROR(__xludf.DUMMYFUNCTION("""COMPUTED_VALUE"""),0.781503141717807) -> 0.78150314 | F11: =IFERROR(__xludf.DUMMYFUNCTION("""COMPUTED_VALUE"""),"") | G11: =IFERROR(__xludf.DUMMYFUNCTION("""COMPUTED_VALUE"""),1.0) -> 1 | H11: =IFERROR(__xludf.DUMMYFUNCTION("""COMPUTED_VALUE"""),0.4779923023475191) -> 0.4779923 | I11: 0.39317502
D12: =IFERROR(__xludf.DUMMYFUNCTION("""COMPUTED_VALUE"""),"") | E12: =IFERROR(__xludf.DUMMYFUNCTION("""COMPUTED_VALUE"""),0.6486927451058364) -> 0.64869275 | F12: =IFERROR(__xludf.DUMMYFUNCTION("""COMPUTED_VALUE"""),"") | G12: =IFERROR(__xludf.DUMMYFUNCTION("""COMPUTED_VALUE"""),"") | H12: =IFERROR(__xludf.DUMMYFUNCTION("""COMPUTED_VALUE"""),0.5953713476386906) -> 0.59537135 | I12: 0.22171032
A13: 0.12985332 | D13: =IFERROR(__xludf.DUMMYFUNCTION("""COMPUTED_VALUE"""),"") | E13: =IFERROR(__xludf.DUMMYFUNCTION("""COMPUTED_VALUE"""),0.6622664840841103) -> 0.66226648 | F13: =IFERROR(__xludf.DUMMYFUNCTION("""COMPUTED_VALUE"""),"") | G13: =IFERROR(__xludf.DUMMYFUNCTION("""COMPUTED_VALUE"""),1.0) -> 1 | H13: =IFERROR(__xludf.DUMMYFUNCTION("""COMPUTED_VALUE"""),0.7607858378948519) -> 0.76078584 | I13: 0.3916452
A14: 0.45941469 | B14: 0 | D14: =IFERROR(__xludf.DUMMYFUNCTION("""COMPUTED_VALUE"""),"") | E14: =IFERROR(__xludf.DUMMYFUNCTION("""COMPUTED_VALUE"""),0.889403590094233) -> 0.88940359 | F14: =IFERROR(__xludf.DUMMYFUNCTION("""COMPUTED_VALUE"""),1.0) -> 1 | G14: =IFERROR(__xludf.DUMMYFUNCTION("""COMPUTED_VALUE"""),1.0) -> 1 | H14: =IFERROR(__xludf.DUMMYFUNCTION("""COMPUTED_VALUE"""),0.4130723542258289) -> 0.41307235 | I14: 0.61365813
A15: 0.11955275 | D15: =IFERROR(__xludf.DUMMYFUNCTION("""COMPUTED_VALUE"""),"") | E15: =IFERROR(__xludf.DUMMYFUNCTION("""COMPUTED_VALUE"""),0.47265371983310933) -> 0.47265372 | F15: =IFERROR(__xludf.DUMMYFUNCTION("""COMPUTED_VALUE"""),"") | G15: =IFERROR(__xludf.DUMMYFUNCTION("""COMPUTED_VALUE"""),1.0) -> 1 | H15: =IFERROR(__xludf.DUMMYFUNCTION("""COMPUTED_VALUE"""),0.9602602357171964) -> 0.96026024 | I15: 0.36418945
A16: 0.24406497 | B16: 0 | D16: =IFERROR(__xludf.DUMMYFUNCTION("""COMPUTED_VALUE"""),"") | E16: =IFERROR(__xludf.DUMMYFUNCTION("""COMPUTED_VALUE"""),0.7518563800998207) -> 0.75185638 | F16: =IFERROR(__xludf.DUMMYFUNCTION("""COMPUTED_VALUE"""),1.0) -> 1 | G16: =IFERROR(__xludf.DUMMYFUNCTION("""COMPUTED_VALUE"""),1.0) -> 1 | H16: =IFERROR(__xludf.DUMMYFUNCTION("""COMPUTED_VALUE"""),0.602145960825503) -> 0.60214596 | I16: 0.59817869
A17: 0.15241021 | D17: =IFERROR(__xludf.DUMMYFUNCTION("""COMPUTED_VALUE"""),"") | E17: =IFERROR(__xludf.DUMMYFUNCTION("""COMPUTED_VALUE"""),0.7306007127585364) -> 0.73060071 | F17: =IFERROR(__xludf.DUMMYFUNCTION("""COMPUTED_VALUE"""),"") | G17: =IFERROR(__xludf.DUMMYFUNCTION("""COMPUTED_VALUE"""),1.0) -> 1 | H17: =IFERROR(__xludf.DUMMYFUNCTION("""COMPUTED_VALUE"""),0.7989645659521445) -> 0.79896457 | I17: 0.41254663
A18: 0.35661765 | B18: 0 | D18: =IFERROR(__xludf.DUMMYFUNCTION("""COMPUTED_VALUE"""),"") | E18: =IFERROR(__xludf.DUMMYFUNCTION("""COMPUTED_VALUE"""),0.715678838128153) -> 0.71567884 | F18: =IFERROR(__xludf.DUMMYFUNCTION("""COMPUTED_VALUE"""),1.0) -> 1 | G18: =IFERROR(__xludf.DUMMYFUNCTION("""COMPUTED_VALUE"""),1.0) -> 1 | H18: =IFERROR(__xludf.DUMMYFUNCTION("""COMPUTED_VALUE"""),0.29191618910194683) -> 0.29191619 | I18: 0.55811133
A19: 0.11223868 | D19: =IFERROR(__xludf.DUMMYFUNCTION("""COMPUTED_VALUE"""),"") | E19: =IFERROR(__xludf.DUMMYFUNCTION("""COMPUTED_VALUE"""),0.7269293584483356) -> 0.72692936 | F19: =IFERROR(__xludf.DUMMYFUNCTION("""COMPUTED_VALUE"""),"") | G19: =IFERROR(__xludf.DUMMYFUNCTION("""COMPUTED_VALUE"""),1.0) -> 1 | H19: =IFERROR(__xludf.DUMMYFUNCTION("""COMPUTED_VALUE"""),0.8638845140738347) -> 0.86388451 | I19: 0.41812079
A20: 0.11082867 | D20: =IFERROR(__xludf.DUMMYFUNCTION("""COMPUTED_VALUE"""),"") | E20: =IFERROR(__xludf.DUMMYFUNCTION("""COMPUTED_VALUE"""),0.10238989523252559) -> 0.1023899 | F20: =IFERROR(__xludf.DUMMYFUNCTION("""COMPUTED_VALUE"""),"") | G20: =IFERROR(__xludf.DUMMYFUNCTION("""COMPUTED_VALUE"""),1.0) -> 1 | H20: =IFERROR(__xludf.DUMMYFUNCTION("""COMPUTED_VALUE"""),0.7467202844151569) -> 0.74672028 | I20: 0.2502695
A21: 0.27339901 | D21: =IFERROR(__xludf.DUMMYFUNCTION("""COMPUTED_VALUE"""),"") | E21: =IFERROR(__xludf.DUMMYFUNCTION("""COMPUTED_VALUE"""),0.8501333696778393) -> 0.85013337 | F21: =IFERROR(__xludf.DUMMYFUNCTION("""COMPUTED_VALUE"""),"") | G21: =IFERROR(__xludf.DUMMYFUNCTION("""COMPUTED_VALUE"""),1.0) -> 1 | H21: =IFERROR(__xludf.DUMMYFUNCTION("""COMPUTED_VALUE"""),0.44025249672534217) -> 0.4402525 | I21: 0.40655859
A22: 0.30637982 | B22: 0 | D22: =IFERROR(__xludf.DUMMYFUNCTION("""COMPUTED_VALUE"""),"") | E22: =IFERROR(__xludf.DUMMYFUNCTION("""COMPUTED_VALUE"""),0.6532759624345169) -> 0.65327596 | F22: =IFERROR(__xludf.DUMMYFUNCTION("""COMPUTED_VALUE"""),1.0) -> 1 | G22: =IFERROR(__xludf.DUMMYFUNCTION("""COMPUTED_VALUE"""),1.0) -> 1 | H22: =IFERROR(__xludf.DUMMYFUNCTION("""COMPUTED_VALUE"""),0.2970836899874542) -> 0.29708369 | I22: 0.54302736
A23: 0.25031712 | D23: =IFERROR(__xludf.DUMMYFUNCTION("""COMPUTED_VALUE"""),"") | E23: =IFERROR(__xludf.DUMMYFUNCTION("""COMPUTED_VALUE"""),1.0) -> 1 | F23: =IFERROR(__xludf.DUMMYFUNCTION("""COMPUTED_VALUE"""),"") | G23: =IFERROR(__xludf.DUMMYFUNCTION("""COMPUTED_VALUE"""),1.0) -> 1 | H23: =IFERROR(__xludf.DUMMYFUNCTION("""COMPUTED_VALUE"""),0.7904562758009703) -> 0.79045628 | I23: 0.47904563
D24: =IFERROR(__xludf.DUMMYFUNCTION("""COMPUTED_VALUE"""),"") | E24: =IFERROR(__xludf.DUMMYFUNCTION("""COMPUTED_VALUE"""),0.7118469843264902) -> 0.71184698 | F24: =IFERROR(__xludf.DUMMYFUNCTION("""COMPUTED_VALUE"""),"") | G24: =IFERROR(__xludf.DUMMYFUNCTION("""COMPUTED_VALUE"""),"") | H24: =IFERROR(__xludf.DUMMYFUNCTION("""COMPUTED_VALUE"""),0.5719683249718881) -> 0.57196833 | I24: 0.23515858
